Workbook

Sheet INPUT_Baseline
A1: OVERALL BASELINE | B1: Based on Nov-Dec25 data
A2: Total Records | B2: 68360
A3: Current Conversion Rate | B3: 0.67
A4: Current Conversions | B4: =B2*B3
A6: CONTACT GROUP BREAKDOWN
A7: Contact Group | B7: Records | C7: Conversion Rate
A8: COUNTER | B8: 35663 | C8: 0.7
A9: HRD-OKC | B9: 25284 | C9: 0.538
A10: NO CONTACT | B10: 7413 | C10: 0.376
B11: =SUM(B8:B10)
A12: MMR BREAKDOWN
A13: Segment | B13: Records | C13: Conversion Rate
A14: MMR | B14: 12267 | C14: 0.73
A15: NO MMR | B15: 56093 | C15: 0.578
A17: MMR BY CONTACT GROUP
A18: Contact Group | B18: MMR (n) | C18: NO MMR (n) | D18: MMR Conv | E18: NO MMR Conv | F18: MMR Lift
A19: COUNTER | B19: 9107 | C19: 26556 | D19: 0.745 | E19: 0.685 | F19: 0.059
A20: HRD-OKC | B20: 3136 | C20: 22148 | D20: 0.694 | E20: 0.516 | F20: 0.177
A21: NO CONTACT | B21: 24 | C21: 7389 | D21: - | E21: - | F21: 0.377
A23: RESPONSE TIME BY CONTACT GROUP
A24: Response Time | B24: COUNTER (n) | C24: HRD-OKC (n) | D24: Gap (pp)
A25: <30min | B25: 15557 | C25: 2521 | D25: 0.06
A26: 30min-1hr | B26: 6729 | C26: 10960 | D26: 0.15
A27: 1-3hr | B27: 6492 | C27: 5787 | D27: 0.18
A28: 3-6hr | B28: 1329 | C28: 1167 | D28: 0.19
A29: 6-12hr | B29: 915 | C29: 576 | D29: 0.18
A30: 12-24hr | B30: 3561 | C30: 3158 | D30: 0.15
A31: 24-48hr | B31: 772 | C31: 771 | D31: 0.14
A32: 48hr+ | B32: 308 | C32: 344 | D32: 0.28
A34: MMR FUNNEL
A35: Stage | B35: Rate | C35: Volume
A36: MMR Sent | B36: 1 | C36: 68360
A37: Clicks Link (Page 1) | B37: 0.322 | C37: 22020
A38: Completes Page 1 | B38: 0.87 | C38: 19157
A39: Completes Page 2 | B39: 0.66 | C39: 12644
A41: SAME-DAY URGENT TRANSFER FUNNEL
A42: (Sample of 677 outbound HRD calls)
A43: Stage | B43: Count | C43: %
A44: All Outbound Calls | B44: 677 | C44: 1
A45: Same-Day Urgent | B45: 253 | C45: 0.37
...

Sheet Summary
A1: HERTZ IR CONVERSION UPLIFT SIZING
A2: CONVERSION RATE SUMMARY
B3: Current Leads | C3: =INPUT_Baseline!B2
B4: Current Conversions | C4: =INPUT_Baseline!B4
B5: Current Conversion Rate | C5: =INPUT_Baseline!B3
B6: New Conversions (LOW) | C6: =INPUT_Baseline!B4+I32
B7: New Conversions (HIGH) | C7: =INPUT_Baseline!B4+J32
B8: New Conversion Rate (LOW) | C8: =(INPUT_Baseline!B4+I32)/INPUT_Baseline!B2
B9: New Conversion Rate (HIGH) | C9: =(INPUT_Baseline!B4+J32)/INPUT_Baseline!B2
B10: Net Improvement (LOW) | C10: =K32
B11: Net Improvement (HIGH) | C11: =L32
B13: Conversion sizing | C13: 1000000 | D13: EBITDA
C14: 0.01 | D14: for every 1%
A16: INITIATIVE DEEP DIVE
A18: # | B18: Initiative | C18: Initiative description | D18: Current State | E18: Problem | F18: Uplift Mechanism | G18: Category | H18: Uplift Lever | I18: Uplift (Conv) LOW | J18: Uplift (Conv) HIGH | K18: Uplift (pp) LOW | L18: Uplift (pp) HIGH | M18: Uplift (EBITDA LOW) $m | N18: Uplift ($ EBITDA HIGH) $m | O18: Timeline
A19: 1 | B19: Remove noise data | C19: # Create a new indicator AUTOCANCEL_IND for all reservations automatically cancelled within 30 minutes by adjustors | D19: All 68,360 records from Nov-Dec 2025 are included in the conversion rate denominator, including auto-cancelled reservations (cancelled within 30 minutes of creation). | E19: These reservations were never real opportunities - the insurance adjuster cancelled before Hertz could contact the customer. Including them in the denominator artificially deflates conversion rate and misrepresents branch performance. | F19: Excluding reservations cancelled by insurance adjusters reduces the total lead count (denominator), which increases the conversion rate to better reflect performance on actionable leads. | G19: Data | H19: Baseline Adjustment | I19: 0 | J19: 0 | K19: 0.021913287 | L19: 0.038043347 | O19: Short term | P19: << No bottomline impact
A20: 2 | B20: Update IVR call tree | C20: # Replace "If you're an insurance company or local account" to "If you need an insurance replacement rental, plress 5" then ask if same-day. If not —> send to HRD) # Move “insurance or bodyshop companies” to press 6 | D20: Current call-tree is confusing, and not intuitive. No customer would agree that "Insurance company or local account" resonates with who they are, but that's the current correct option for an IR lead | E20: Branch becomes uncontactable, or customer gets stuck in other call tree options which try to defer them out from speaking to anyone. We hear them complaining to HRD about branch being impossible to reach | F20: Updating the call tree makes it easier for customers to reach the branch directly, shifting volume from NO CONTACT/HRD to COUNTER and capturing the conversion advantage. | G20: Central / CX | H20: Higher Branch Contact (Inbound) | I20: ='2_CallTree'!B20 | J20: ='2_CallTree'!B21 | K20: 0.0037574671 | L20: 0.0075149342 | M20: 0.3757 | N20: 0.7515 | O20: Short term
A21: 3 | B21: HRD verbiage update | C21: # Make sure no mention of "Branch discretion", "not guaranteed", "not confirmed". Be like the MMR, main objectives are to (1) establish rapport, (2) cement commitment. | D21: HRD agents are mentioning phrases that kill confidence and trust, such as "your pick up is not guaranteed". "It's at the branch's discretion", "your reservation is not yet confirmed, please call branch to confirm it" | E21: This creates leakage / friction points, makes customers feel frustrated. Customers definitely do not appreciate uncertainty, especially after spending 10 minutes with an HRD agents | F21: Fixing the verbiage will help HRD agents achieve similar outcomes to MMR-driven conversion, as it will achieve the same level of commitment despite not being able to confirm anything. | G21: Central / CX | H21: Higher HRD Conversion | I21: ='3_HRDVerbiage'!B20 | J21: ='3_HRDVerbiage'!B21 | K21: 0.00173 | L21: 0.002884 | M21: 0.173 | N21: 0.2884 | O21: Short term
A22: 4 | B22: HRD SOP - warm transfer for all immediate need (same day and pick up requested) | C22: # Do not cold transfer (this is breaking SOP) # Always warm transfer immediate-need (Same day and pick up requested) | D22: 37% of HRD calls are same-day urgent pickups. Currently only 33% of these get transferred to branch, only 68% of transfers are warm (agent stays on line), and only 61% of warm transfers result in branch answering. Net: only ~14% of same-day urgent calls successfully reach the branch. | E22: Same-day customers need immediate help and have high intent. Cold transfers are lazy and frustrating to the customer because customer has to repeat everything again to branch, breaks trust. | F22: Warm transferring all same-day urgent calls increases the percentage of high-intent customers who successfully reach the branch. The uplift is calculated by comparing the current funnel (transfer rate × warm rate × answer rate) to the target funnel, then applying the conversion delta between urgent customers reaching branch versus standard HRD conversion to the incremental volume. | G22: Central / CX | H22: Higher Branch Contact (Inbound) | I22: ='4_HRDWarmTransfer'!B38 | J22: ='4_HRDWarmTransfer'!B39 | K22: 0.0076708588 | L22: 0.011114306 | M22: 0.7671 | N22: 1.1114 | O22: Immediate
A23: 5 | B23: MMR Page 1: Reminder SMS/email | C23: # Send a scheduled reminder to the MMR link after 6 hours if not yet clicked, and reservation is not yet opened | D23: MMR link is sent once when the reservation is created. Only 32.2% of customers click through to start the form. No follow-up is sent if customers don't engage. | E23: Customers miss or ignore the initial message - it may arrive at an inconvenient time, get buried in other notifications, or not clearly convey urgency. Without a reminder, 67.8% of customers never enter the MMR funnel. | F23: Sending a reminder increases the percentage of customers who click the MMR link. Additional clickers flow through the MMR funnel and gain the blended MMR conversion lift upon completion. | G23: Tech | H23: Higher MMR Completion | I23: ='5_MMRPage1'!B24 | J23: ='5_MMRPage1'!B25 | K23: 0.006142 | L23: 0.014016 | M23: 0.6142 | N23: 1.4016 | O23: Immediate
A24: 6 | B24: MMR Page 2: UX improvements | C24: # Page 2 improvements: - Remove the confirmation screen - Cover for scenarios where (1) body shop not yet confirmed; (2) want to pick up at locations outside of bodyshop; (3) same day urgent pick up to override current guardrails (2 hours notice, 2 hours from shop closing, 1 hour from shop opening) - Have an express flow for same day urgent pick ups and unknown body shop - Remove picture of car / phone number of branch - Allow customer to update bodyshop location after confirmation | D24: 87% of customers who click complete Page 1, but only 66% complete Page 2 - a 34% drop-off rate. Page 2 has friction including confusing fields and unclear flow. No option exists for customers who don't have a bodyshop yet. The confirmation screen (Page 3) may not clearly confirm the reservation is complete. | E24: Page 2 friction causes abandonment before MMR completion. Customers who start but don't finish MMR get no benefit from the partial completion. The drop-off represents lost conversion lift on engaged customers. | F24: Improving Page 2 UX reduces form abandonment, increasing the number of customers who complete MMR. Additional completers gain the blended MMR conversion lift. | G24: Tech | H24: Higher MMR Completion | I24: ='6_MMRPage2'!B24 | J24: ='6_MMRPage2'!B25 | K24: 0.006338 | L24: 0.008874 | M24: 0.6338 | N24: 0.8874 | O24: Medium term
A25: 5-6 | B25: MMR Interaction Effect (Initiatives 5+6 combined) | C25: When both MMR initiatives are implemented together, the compounding effect creates additional uplift beyond the sum of individual initiatives. | D25: Initiatives 5 and 6 target different stages of the MMR funnel (click rate and Page 2 completion). | E25: Calculating uplifts separately misses the interaction - more clicks flowing through better Page 2 completion. | F25: Interaction uplift = Init 5 lift % × Init 6 lift % × baseline MMR completions × MMR conversion lift. This captures the compounding effect when both initiatives are implemented together. | G25: Tech | H25: Higher MMR Completion | I25: 104.96053 | J25: 335.33542 | K25: 0.0015354008 | L25: 0.0049055003 | M25: 0.15354008 | N25: 0.49055003 | O25: Medium term
A26: 7 | B26: Branch: 15-min HLES queue check | C26: # Implement an EDI owner at different parts of the day (AM/PM), the owner has to check HLES every 15 minutes (timer) | D26: Branch staff check the HLES queue for new IR leads on an ad-hoc basis. It's owned by everyone, which without clear ownership, will get deprioritized once people are busy. There's no systematic reminder to check regularly, so leads can sit in queue while staff handle other tasks. | E26: Leads sitting in queue don't get contacted. Every minute of delay reduces conversion probability - response time data shows clear correlation between faster contact and higher conversion. Leads contacted by HRD first (because branch didn't check queue) convert 16.2pp lower. | F26: Volume shift uplift: Branch intercepts HRD leads faster. Uplift = shifted volume × (COUNTER conv - HRD conv). Split 50% with Initiative 8. | G26: Branch / Ops | H26: Faster Counter Contact | I26: ='7-8_Branch-FasterContact'!B27*0.5 | J26: ='7-8_Branch-FasterContact'!B28*0.5 | K26: 0.0044933909 | L26: 0.0067400863 | M26: 0.4493 | N26: 0.674 | O26: Short term
A27: 8 | B27: Branch: Phone discipline | C27: #Ensure phones are never muted # Never let the phone ring out, always pick up and ask customer to hold if busy. | D27: Branch phones may be muted or set to do-not-disturb at certain branches, esp. during busy periods. They then often forget to unmute. When phones ring, staff may let them ring out rather than answering immediately. Inbound calls from customers or HRD transfers go unanswered. | E27: Muted phones mean missed calls from high-intent customers calling to confirm their rental. Letting phones ring out loses same-day urgent transfers from HRD and direct customer calls. We know that when put on hold, customers will stay on the line (as long as they've heard a voice on the other side) | F27: Volume shift uplift: Phone discipline ensures calls are answered. Uplift = shifted volume × (COUNTER conv - HRD conv). Split 50% with Initiative 7. | G27: Branch / Ops | H27: Faster Counter Contact | I27: ='7-8_Branch-FasterContact'!B27*0.5 | J27: ='7-8_Branch-FasterContact'!B28*0.5 | K27: 0.0044933909 | L27: 0.0067400863 | M27: 0.4493 | N27: 0.674 | O27: Short term
A28: 9 | B28: Branch: Leadership cascade on IR importance | C28: # Restate the improtance of IR leads, from both a growth area perspective, but also Average Contract Value perspective. Drive this down at every level. | D28: IR lead conversion may not be consistently emphasized as a priority across all management levels. Branch staff may not fully understand the revenue impact of each converted lead. Day-to-day still focused on retail/booked reservation, not winning new reservation. | E28: Without clear leadership emphasis, IR leads compete with other priorities. Staff may not treat IR leads with appropriate urgency. Inconsistent messaging across management levels leads to inconsistent execution. | F28: Conversion improvement: Leadership emphasis drives consistent IR prioritization, improving COUNTER conversion by ~3%. Split equally across Initiatives 9-11. | G28: Branch / Ops | H28: Improved Branch Conversion | I28: ='9-11_Branch-BetterConversion'!B18/3 | J28: ='9-11_Branch-BetterConversion'!B19/3 | K28: 0.0036518578 | L28: 0.0060864297 | M28: 0.3652 | N28: 0.6086 | O28: Short term
A29: 10 | B29: Branch: Weekly unconverted lead reviews | C29: # Roulette-style weekly IR lead reviews between GM and all BMs. All BMs must submit their lead reports, but only 2-3 BMs reports get walked through in the session. Celebrate conversion, share key learnings, and track every single non-converted leads. Reasons if cancelled, next steps if unused. | D29: No systematic review process exists for unconverted leads. Leads that don't convert are not analyzed for patterns or root causes. Lost opportunities aren't used as learning moments, and no opportunity to cement accountability | E29: Without reviewing unconverted leads, branches can't identify what went wrong or improve their approach. Patterns (e.g., specific bodyshops, time-of-day issues, staffing gaps) go undetected. Same mistakes repeat. | F29: Conversion improvement: Reviewing unconverted leads identifies improvement opportunities, improving COUNTER conversion by ~3%. Split equally across Initiatives 9-11. | G29: Branch / Ops | H29: Improved Branch Conversion | I29: ='9-11_Branch-BetterConversion'!B18/3 | J29: ='9-11_Branch-BetterConversion'!B19/3 | K29: 0.0036518578 | L29: 0.0060864297 | M29: 0.3652 | N29: 0.6086 | O29: Short term
A30: 11 | B30: Branch: Escalation path for unanswered transfers | C30: # do 2 branch transfer attempts to give branch the opportunity to pick up and ask to hold # Start reviewing/tracking escalations (similar to fleet leads) | D30: When HRD attempts to warm transfer a call and the branch doesn't answer, they submit an escalation but the escalation protocol is not tracked/followed up. Escalations can be easily ignored | E30: Failed transfers lose high-intent customers who were ready to book. While escalations may help, it's currently a one way flow that goes from HRD --> Team lead --> ZGM --> BM with no proper follow up. It assumes BM will take action, and no update required internally | F30: Conversion improvement: Clear escalation paths recover failed transfers, improving COUNTER conversion by ~3%. Split equally across Initiatives 9-11. | G30: Branch / Ops | H30: Improved Branch Conversion | I30: ='9-11_Branch-BetterConversion'!B18/3 | J30: ='9-11_Branch-BetterConversion'!B19/3 | K30: 0.0036518578 | L30: 0.0060864297 | M30: 0.3652 | N30: 0.6086 | O30: Medium term
A31: 12-13 | B31: Bodyshop: 'Protect your lunch' outreach | C31: # Call bodyshop right after confirming with the customer, to confirm the customer's appointment time, and inform them Hertz will be there to pick them up # Ensure Hertz team member arrives at body shop for pick up 5 minute early and never late. Wait inside the bodyshop office, and build relationship with them in the meantime. | D31: After a reservation is made, there's often no proactive outreach to the bodyshop. Bodyshop will be more aggressive at trying to flip when they don't know if the customer has already been in contact with a provider. Customers arrive at bodyshops where staff may have relationships with competitor rental companies. Estimate ~5% of non Insurance Partner driven cancellations are due to flips | E31: Bodyshop staff interact with customers before Hertz does at pickup. Without a Hertz relationship, bodyshop staff may steer customers to competitors they have deals with. Each flip is a lost rental that was already in our system. Customers do not like to wait. The moment they need to wait, they will look for alternatives, especially if Enterprise is visible and bodyshop insists they have cars and customer can leave in 5 minutes (get along with their day) | F31: Calling the bodyshop after reservation confirms Hertz's presence, reducing the chance that bodyshop staff steer customers to competitors. Prevented flips convert at 100% since they were already booked. Arriving early and showing face will definitely prevent flips. Uplift is driven by reduced flips | G31: Branch / Ops | H31: Reduced Competitor Flips | I31: ='12-13_Bodyshop'!B22 | J31: ='12-13_Bodyshop'!B23 | K31: 0.00495 | L31: 0.012375 | M31: 0.495 | N31: 1.2375 | O31: Immediate term
I32: =SUM(I19:I31) | J32: =SUM(J19:J31) | K32: =SUM(K19:K31) | L32: =SUM(L19:L31) | M32: =SUM(M19:M31) | N32: =SUM(N19:N31)

Sheet 1_DataCleanup
A2: UPLIFT ASSUMPTIONS
A3: Noise records - LOW (EDI cancelled within 10 min) | B3: 2165 | C3: Source: TRANSLOG - EDI cancellations within 10 min (2,209 × 98%)
A4: Noise records - HIGH (EDI cancelled within 60 min) | B4: 3673 | C4: Source: TRANSLOG - EDI cancellations within 60 min (10min + 30min + 60min buckets)
A5: BASELINE INPUTS
A6: Total Records | B6: =INPUT_Baseline!B2
A7: Current Conversions | B7: =INPUT_Baseline!B4
A8: Current Conversion Rate | B8: =INPUT_Baseline!B3
A10: CALCULATION
A11: Noise Records (low) | B11: =B3
A12: Noise Records (high) | B12: =B4
A13: Adjusted Total Records (low) | B13: =B6-B11
A14: Adjusted Total Records (high) | B14: =B6-B12
A15: Current Conversions (unchanged) | B15: =B7
A16: Adjusted Conversion Rate (low) | B16: =B7/B13
A17: Adjusted Conversion Rate (high) | B17: =B7/B14
A19: OUTPUT
A20: Records Removed (low) | B20: =B11
A21: Records Removed (high) | B21: =B12
A22: Conversion Rate Lift (low) | B22: =B16-B8
A23: Conversion Rate Lift (high) | B23: =B17-B8

Sheet 2_CallTree
A2: UPLIFT ASSUMPTIONS
A3: Shift % (low) | B3: 0.05 | C3: Source: Conservative assumption
A4: Shift % (high) | B4: 0.1 | C4: Source: Aggressive assumption
A6: BASELINE INPUTS
A7: NO CONTACT Records | B7: =INPUT_Baseline!B10
A8: NO CONTACT Conversion Rate | B8: 0.007 | C8: Source: This is the non-Licensee success rate (Licensee data skews averages since 99% of their leads do not have contact data)
A9: COUNTER Conversion Rate | B9: =INPUT_Baseline!C8
A10: Total Records (for pp calc) | B10: =INPUT_Baseline!B2
A12: CALCULATION
A13: Volume Shifted (low) | B13: =B7*B3
A14: Volume Shifted (high) | B14: =B7*B4
A15: Conversion Delta | B15: =B9-B8
A16: Uplift (low) | B16: =B13*B15
A17: Uplift (high) | B17: =B14*B15
A19: OUTPUT
A20: Additional Conversions (low) | B20: =B16
A21: Additional Conversions (high) | B21: =B17
A22: Uplift % pts (low) | B22: =B20/B10
A23: Uplift % pts (high) | B23: =B21/B10

Sheet 3_HRDVerbiage
A2: UPLIFT ASSUMPTIONS
A3: Gap Close % (low) | B3: 0.15 | C3: Source: Conservative assumption
A4: Gap Close % (high) | B4: 0.25 | C4: Source: Optimistic assumption
A5: % of calls with bad verbiage | B5: 0.2 | C5: assume 20% of HRD calls have problematic verbiage
A6: BASELINE INPUTS
A7: HRD + NO MMR Records | B7: 22148
A8: HRD + NO MMR Conversion Rate | B8: 0.516
A9: HRD + MMR Conversion Rate | B9: 0.694
A10: Total Records (for pp calc) | B10: 68360
A12: CALCULATION
A13: Conversion Gap | B13: 0.178
A14: Improvement (low) | B14: 0.0267
A15: Improvement (high) | B15: 0.0445
A16: Uplift (low) | B16: 118.27032
A17: Uplift (high) | B17: 197.1172
A19: OUTPUT
A20: Additional Conversions (low) | B20: 118.27032
A21: Additional Conversions (high) | B21: 197.1172
A22: Uplift % pts (low) | B22: 0.00173011
A23: Uplift % pts (high) | B23: 0.0028835167

Sheet 4_HRDWarmTransfer
A2: UPLIFT ASSUMPTIONS
A4: Immediate Need % of HRD | B4: 0.133 | C4: Source: 90/677 calls = Pickup Requested segment
A5: Current Transfer % | B5: 0.62 | C5: Source: 56/90 currently transferred
A6: Target Transfer % | B6: 1 | C6: Source: Process change - all immediate need transferred
A7: Current Warm % | B7: 0.68 | C7: Source: 57/84 currently warm transferred
A8: Target Warm % | B8: 1 | C8: Source: Process change - no cold transfers
A9: Current Branch Answer % | B9: 0.61 | C9: Source: 35/57 branch answered
A10: Target Branch Answer % (low) | B10: 0.65 | C10: Source: Conservative target
A11: Target Branch Answer % (high) | B11: 0.75 | C11: Source: Optimistic target with escalation protocol
A12: Cold Transfer Conversion | B12: 0.6 | C12: Source: Cold transfer still converts but at lower rate
A13: Warm Transfer Conversion | B13: 0.7 | C13: Source: HRD (53.8%) and COUNTER (70%); conservative let's use COUNTER
A15: BASELINE INPUTS
A16: Total HRD Records | B16: =INPUT_Baseline!B9
A17: Total Records (for pp calc) | B17: =INPUT_Baseline!B2
A19: CALCULATION
A20: Immediate Need Volume | B20: =B16*B4
A21: Current: Transferred | B21: =B20*B5
A22: Current: Warm transfers reaching branch | B22: =B21*B7*B9
A23: Current: Cold transfers | B23: =B21*(1-B7)
A24: Current: Conversions from warm | B24: =B22*B13
A25: Current: Conversions from cold | B25: =B23*B12
A26: Current: Total Conversions | B26: =B24+B25
A28: Target: Transferred | B28: =B20*B6
A29: Target: Warm transfers reaching branch (low) | B29: =B28*B8*B10
A30: Target: Warm transfers reaching branch (high) | B30: =B28*B8*B11
A31: Target: Conversions (low) | B31: =B29*B13
A32: Target: Conversions (high) | B32: =B30*B13
A34: Uplift (low) | B34: =B31-B26
A35: Uplift (high) | B35: =B32-B26
A37: OUTPUT
A38: Additional Conversions (low) | B38: =B34
A39: Additional Conversions (high) | B39: =B35
A40: Uplift % pts (low) | B40: =B38/B17
A41: Uplift % pts (high) | B41: =B39/B17

Sheet 5_MMRPage1
A2: UPLIFT ASSUMPTIONS
A3: Reminder Lift on Click Rate (low) | B3: 0.24223602 | C3: Target: 40% click rate (vs 32.2% baseline)
A4: Reminder Lift on Click Rate (high) | B4: 0.55279503 | C4: Target: 50% click rate (vs 32.2% baseline)
A6: BASELINE INPUTS
A7: Total Records | B7: 68360
A8: Current Click Rate | B8: 0.322
A9: Page 1 Completion Rate | B9: 0.87
A10: Page 2 Completion Rate | B10: 0.66
A11: Blended MMR Conversion Lift | B11: 0.137128
A13: CALCULATION
A14: New Click Rate (low) | B14: 0.4
A15: New Click Rate (high) | B15: 0.5
A16: Additional Clickers (low) | B16: 5332.08
A17: Additional Clickers (high) | B17: 12168.08
A18: Additional MMR Completions (low) | B18: 3061.6803
A19: Additional MMR Completions (high) | B19: 6986.9115
A20: Uplift (low) | B20: 419.8421
A21: Uplift (high) | B21: 958.10121
A23: OUTPUT
A24: Additional Conversions (low) | B24: 419.8421
A25: Additional Conversions (high) | B25: 958.10121
A26: Uplift % pts (low) | B26: 0.006141634
A27: Uplift % pts (high) | B27: 0.014015524

Sheet 6_MMRPage2
A2: UPLIFT ASSUMPTIONS
A3: UX Lift on Page 2 Completion (low) | B3: 0.25 | C3: UX optimization: 25% lift on Page 2 completion
A4: UX Lift on Page 2 Completion (high) | B4: 0.35 | C4: UX optimization: 35% lift on Page 2 completion
A6: BASELINE INPUTS
A7: Current Page 1 Completers | B7: 19150.37
A8: Current Page 2 Completion Rate | B8: 0.66
A9: Blended MMR Conversion Lift | B9: 0.137128
A10: Total Records (for pp calc) | B10: 68360
A12: CALCULATION
A13: New Page 2 Rate (low) | B13: 0.825
A14: New Page 2 Rate (high) | B14: 0.891
A15: Current Page 2 Completers | B15: 12639.244
A16: New Page 2 Completers (low) | B16: 15799.056
A17: New Page 2 Completers (high) | B17: 17062.98
A18: Additional Completions (low) | B18: 3159.8111
A19: Additional Completions (high) | B19: 4423.7356
A20: Uplift (low) | B20: 433.29858
A21: Uplift (high) | B21: 606.61801
A23: OUTPUT
A24: Additional Conversions (low) | B24: 433.29858
A25: Additional Conversions (high) | B25: 606.61801
A26: Uplift % pts (low) | B26: 0.0063384813
A27: Uplift % pts (high) | B27: 0.0088738738

Sheet 7-8_Branch-FasterContact
A2: UPLIFT ASSUMPTIONS
A3: Shift % for HRD <30min to COUNTER (low) | B3: 0.2 | C3: Source: Conservative estimate
A4: Shift % for HRD <30min to COUNTER (high) | B4: 0.3 | C4: Source: Optimistic estimate
A5: Shift % for HRD 30min-1hr to COUNTER (low) | B5: 0.3 | C5: Source: Conservative estimate
A6: Shift % for HRD 30min-1hr to COUNTER (high) | B6: 0.45 | C6: Source: Optimistic estimate
A8: BASELINE INPUTS
A9: HRD <30min Records | B9: =INPUT_Baseline!C25
A10: HRD 30min-1hr Records | B10: =INPUT_Baseline!C26
A11: COUNTER Conversion Rate | B11: =INPUT_Baseline!C8
A12: HRD Conversion Rate | B12: =INPUT_Baseline!C9
A13: Total Records (for pp calc) | B13: =INPUT_Baseline!B2
A15: CALCULATION
A16: Volume Shifted <30min (low) | B16: =B9*B3
A17: Volume Shifted 30min-1hr (low) | B17: =B10*B5
A18: Total Volume Shifted (low) | B18: =B16+B17
A19: Volume Shifted <30min (high) | B19: =B9*B4
A20: Volume Shifted 30min-1hr (high) | B20: =B10*B6
A21: Total Volume Shifted (high) | B21: =B19+B20
A22: Conversion Delta (COUNTER vs HRD) | B22: =B11-B12
A23: Uplift (low) | B23: =B18*B22
A24: Uplift (high) | B24: =B21*B22
A26: OUTPUT
A27: Additional Conversions (low) | B27: =B23
A28: Additional Conversions (high) | B28: =B24
A29: Uplift % pts (low) | B29: =B27/B13
A30: Uplift % pts (high) | B30: =B28/B13

Sheet 9-11_Branch-BetterConversion
A2: UPLIFT ASSUMPTIONS
A3: COUNTER Conversion Improvement (low) | B3: 0.03 | C3: Source: Conservative estimate
A4: COUNTER Conversion Improvement (high) | B4: 0.05 | C4: Source: Optimistic estimate
A5: Current COUNTER conversion rate | B5: =INPUT_Baseline!C8
A7: BASELINE INPUTS
A8: COUNTER Records | B8: =INPUT_Baseline!B8
A9: Total Records (for pp calc) | B9: =INPUT_Baseline!B2
A11: CALCULATION
A12: Conversion Improvement (low) | B12: =B3*B5
A13: Conversion Improvement (high) | B13: =B4*B5
A14: Uplift (low) | B14: =B8*B12
A15: Uplift (high) | B15: =B8*B13
A17: OUTPUT
A18: Additional Conversions (low) | B18: =B14
A19: Additional Conversions (high) | B19: =B15
A20: Uplift % pts (low) | B20: =B18/B9
A21: Uplift % pts (high) | B21: =B19/B9

Sheet 12-13_Bodyshop
A2: UPLIFT ASSUMPTIONS
A3: Bodyshop Flip % of Cancellations (low) | B3: 0.03 | C3: Source: Conservative estimate
A4: Bodyshop Flip % of Cancellations (high) | B4: 0.05 | C4: Source: Optimistic estimate
A5: Prevention Rate with initiative (low) | B5: 0.5 | C5: Source: Conservative estimate
A6: Prevention Rate with initiative (high) | B6: 0.75 | C6: Source: Optimistic estimate
A8: BASELINE INPUTS
A9: Total Records | B9: =INPUT_Baseline!B2
A10: Current Conversion Rate | B10: =INPUT_Baseline!B3
A12: CALCULATION
A13: Total Cancellations | B13: =B9*(1-B10)
A14: Bodyshop Flips (low) | B14: =B13*B3
A15: Bodyshop Flips (high) | B15: =B13*B4
A16: Flips Prevented (low) | B16: =B14*B5
A17: Flips Prevented (high) | B17: =B15*B6
A18: Uplift (low) | B18: =B16
A19: Uplift (high) | B19: =B17
A21: OUTPUT
A22: Additional Conversions (low) | B22: =B18
A23: Additional Conversions (high) | B23: =B19
A24: Uplift % pts (low) | B24: =B22/B9
A25: Uplift % pts (high) | B25: =B23/B9
